Workbook

Sheet BASE DE DATOS DE PRODUCTOS
A1: LISTA DE PRODUCTOS
A5: CODIGO | B5: NOMBRE DEL PRODUCTO | C5: CATEGORIA | D5: OBSERVACIÓN
A6: A001 | B6: DETERGENTE BIO AZUL DE 5 LITROS | C6: LAVANDERIA
A7: A002 | B7: DETERGENTE BIO VERDE DE 5 LITROS | C7: LAVANDERIA
A8: A003 | B8: DETERGENTE MORADO CON SUAVIZANTE DE 5 LITROS | C8: LAVANDERIA
A9: A004 | B9: DETERGENTE BLANCO CON SUAVIZANTE DE 5 LITROS | C9: LAVANDERIA
A10: A005 | B10: DETERGENTE CELESTE CON SUAVIZANTE DE 5 LITROS | C10: LAVANDERIA
A11: A006 | B11: DETERGENTE NARANJO CON SUAVIZANTE DE 5 LITROS | C11: LAVANDERIA
A12: A007 | B12: DETERGENTE ROSADO CON SUAVIZANTE DE 5 LITROS | C12: LAVANDERIA
A13: A008 | B13: DETERGENTE PREMIUM AROMA OMO DE 3 LITROS (PACK DE 4 UNID) | C13: LAVANDERIA
A14: A009 | B14: DETERGENTE DE BEBÉ 3 LITROS | C14: LAVANDERIA
A15: A010 | B15: DETERGENTE OMO PARA DILUIR 3 LITROS | C15: LAVANDERIA
A16: A011 | B16: DETERGENTE OMO DE 400 ML | C16: LAVANDERIA
A17: A012 | B17: DETERGENTE OMO LIQUIDO BIDÓN 3 LITROS | C17: LAVANDERIA | D17: ME FALTA COMPRAR
A18: A013 | B18: DETERGENTE BIO KLINNING AZUL | C18: LAVANDERIA | D18: ME FALTA COMPRAR
A19: A014 | B19: DETERGENTE BIO KLINNING VERDE | C19: LAVANDERIA | D19: ME FALTA COMPRAR
A20: A015 | B20: DETERGENTE SOFT LIQUIDO BIDÓN DE 3 LITROS | C20: LAVANDERIA | D20: ME FALTA COMPRAR
A21: A016 | B21: DETERGENTE EN POLVO QUITA MANCHA ROSADO | C21: LAVANDERIA
A22: A017 | B22: DETERGENTE EN POLVO QUITA MANCHA MORADO | C22: LAVANDERIA
A23: A018 | B23: DETERGENTE EN POLVO VIRGINIA | C23: LAVANDERIA
A24: A019 | B24: CLORO ROPA BLANCA SPUM DE 1 LITRO | C24: LAVANDERIA
A25: A020 | B25: CLORO ROPA A COLOR SPUM DE 1 LITRO | C25: LAVANDERIA
A26: A021 | B26: VANISH BLANCO | C26: LAVANDERIA | D26: ME FALTA COMPRAR
A27: A022 | B27: VANISH ROSADO | C27: LAVANDERIA | D27: ME FALTA COMPRAR
A28: A023 | B28: CLORO CONCENTRADO DE 5 LITROS | C28: DESINFECCIÓN
A29: A024 | B29: CLORINDA DE 1 LITRO | C29: DESINFECCIÓN | D29: ME FALTA COMPRAR
A30: A025 | B30: CLORO GEL CLOROX | C30: DESINFECCIÓN | D30: ME FALTA COMPRAR
A31: A026 | B31: CLORO IGENIX LIQUIDO | C31: DESINFECCIÓN
A32: A027 | B32: CLORINDA CLORO GEL | C32: DESINFECCIÓN
A33: A028 | B33: CLORINDA CLORO GEL EXCEL MORADO | C33: DESINFECCIÓN
A34: A029 | B34: CLORINDA CLORO GEL EXCEL AMARILLO | C34: DESINFECCIÓN
A35: A030 | B35: ANTIGRASA SPUM DE 2 LITROS | C35: COCINA
A36: A031 | B36: ANTIGRASA SPUM DE 500 ML | C36: COCINA
A37: A032 | B37: SACASARRO SPUM DE 2 LITROS | C37: COCINA
A38: A033 | B38: SACASARRO SPUM DE 500 ML | C38: COCINA
A39: A034 | B39: LAVALOSA SPUM DE 1 LITRO | C39: COCINA
A40: A035 | B40: LAVALOSA SPUM DE 2 LITROS | C40: COCINA
A41: A036 | B41: LAVALOSA SPUM DE 5 LITROS | C41: COCINA
A42: A037 | B42: LAVALOSA QUIX | C42: COCINA | D42: ME FALTA COMPRAR
A43: A038 | B43: CIF | C43: COCINA
...

Sheet Hoja1
C3: detalle | E3: stock | F3: compra
C4: detergente saca mancha lavanda | E4: 5 | F4: 6
C5: detergente saca mancha floral | E5: 6 | F5: 6
C6: detergente virginia | E6: 6 | F6: 6
C7: omo para diluir | E7: 14 | F7: 24
C8: omo liquido 400ml | E8: 7 | F8: 12
C9: shampoo familand granada | E9: 3 | F9: 6
C10: acondicionador familand | E10: 4 | F10: 6
C11: shampoo dove | E11: 5 | F11: 6
C12: acondicionador dove | E12: 5 | F12: 6
C13: shampoo ballerina | E13: 5
C14: acondicionador ballerina | E14: 8
C15: spum de bebe | E15: 5 | F15: 4
C16: detergente bio | E16: 14 | F16: 12
C17: cloro gel limon | E17: 5 | F17: 5
C18: cloro gel lavanda | E18: 5 | F18: 5
C19: trapero deseshable limon
C20: trapero deseshable lavanda
C21: desodorante ambiental poett

Sheet PARAMETROS
A5: CATEGORIAS
A6: LAVANDERIA
A7: DESINFECCIÓN
A8: COCINA
A9: SUPERFICIE
A10: AMBIENTADORES
A11: HIGIENE PERSONAL
A12: ACCESORIOS DE LIMPIEZA
A13: PLAGAS
A14: RESIDUOS

Sheet INVENTARIO
A1: INVENTARIO
J4: TOTAL INVENTARIO
J5: =SUBTOTAL(9,INVENTARIO[[#All],[VALOR DEL INVENTARIO]]) -> 1059018
A6: CODIGO | B6: NOMBRE DEL PRODUCTO | C6: CATEGORIA | D6: COMPRAS | E6: VENTAS | F6: STOCK | G6: COSTO UNITARIO | H6: PRECIO DE VENTA | I6: UTILIDAD POR PRODUCTO | J6: VALOR DEL INVENTARIO | K6: GANANCIA TOTAL DE CADA PRODFUCTO
A7: A001 | B7: =IFERROR(VLOOKUP(INVENTARIO[[#This Row],[CODIGO]],BASEDEDATOS[],2,FALSE),"NO EXISTE") -> DETERGENTE BIO AZUL DE 5 LITROS | C7: =IFERROR(VLOOKUP(INVENTARIO[[#This Row],[CODIGO]],BASEDEDATOS[],3,FALSE),"NO EXISTE") -> LAVANDERIA | D7: 150 | E7: 11 | F7: =INVENTARIO[[#This Row],[COMPRAS]]-INVENTARIO[[#This Row],[VENTAS]] -> 139 | G7: 920 | H7: 1800 | I7: =INVENTARIO[[#This Row],[PRECIO DE VENTA]]-INVENTARIO[[#This Row],[COSTO UNITARIO]] -> 880 | J7: =INVENTARIO[[#This Row],[COSTO UNITARIO]]*INVENTARIO[[#This Row],[STOCK]] -> 127880 | K7: =+INVENTARIO[[#This Row],[VENTAS]]*INVENTARIO[[#This Row],[UTILIDAD POR PRODUCTO]] -> 9680
A8: A002 | B8: =IFERROR(VLOOKUP(INVENTARIO[[#This Row],[CODIGO]],BASEDEDATOS[],2,FALSE),"NO EXISTE") -> DETERGENTE BIO VERDE DE 5 LITROS | C8: =IFERROR(VLOOKUP(INVENTARIO[[#This Row],[CODIGO]],BASEDEDATOS[],3,FALSE),"NO EXISTE") -> LAVANDERIA | D8: 50 | E8: 8 | F8: =INVENTARIO[[#This Row],[COMPRAS]]-INVENTARIO[[#This Row],[VENTAS]] -> 42 | G8: 920 | H8: 1800 | I8: =INVENTARIO[[#This Row],[PRECIO DE VENTA]]-INVENTARIO[[#This Row],[COSTO UNITARIO]] -> 880 | J8: =INVENTARIO[[#This Row],[COSTO UNITARIO]]*INVENTARIO[[#This Row],[STOCK]] -> 38640 | K8: =+INVENTARIO[[#This Row],[VENTAS]]*INVENTARIO[[#This Row],[UTILIDAD POR PRODUCTO]] -> 7040
A9: A003 | B9: =IFERROR(VLOOKUP(INVENTARIO[[#This Row],[CODIGO]],BASEDEDATOS[],2,FALSE),"NO EXISTE") -> DETERGENTE MORADO CON SUAVIZANTE DE 5 LITROS | C9: =IFERROR(VLOOKUP(INVENTARIO[[#This Row],[CODIGO]],BASEDEDATOS[],3,FALSE),"NO EXISTE") -> LAVANDERIA | D9: 10 | E9: 4 | F9: =INVENTARIO[[#This Row],[COMPRAS]]-INVENTARIO[[#This Row],[VENTAS]] -> 6 | G9: 1490 | H9: 2500 | I9: =INVENTARIO[[#This Row],[PRECIO DE VENTA]]-INVENTARIO[[#This Row],[COSTO UNITARIO]] -> 1010 | J9: =INVENTARIO[[#This Row],[COSTO UNITARIO]]*INVENTARIO[[#This Row],[STOCK]] -> 8940 | K9: =+INVENTARIO[[#This Row],[VENTAS]]*INVENTARIO[[#This Row],[UTILIDAD POR PRODUCTO]] -> 4040
A10: A004 | B10: =IFERROR(VLOOKUP(INVENTARIO[[#This Row],[CODIGO]],BASEDEDATOS[],2,FALSE),"NO EXISTE") -> DETERGENTE BLANCO CON SUAVIZANTE DE 5 LITROS | C10: =IFERROR(VLOOKUP(INVENTARIO[[#This Row],[CODIGO]],BASEDEDATOS[],3,FALSE),"NO EXISTE") -> LAVANDERIA | D10: 60 | E10: 2 | F10: =INVENTARIO[[#This Row],[COMPRAS]]-INVENTARIO[[#This Row],[VENTAS]] -> 58 | G10: 1490 | H10: 2500 | I10: =INVENTARIO[[#This Row],[PRECIO DE VENTA]]-INVENTARIO[[#This Row],[COSTO UNITARIO]] -> 1010 | J10: =INVENTARIO[[#This Row],[COSTO UNITARIO]]*INVENTARIO[[#This Row],[STOCK]] -> 86420 | K10: =+INVENTARIO[[#This Row],[VENTAS]]*INVENTARIO[[#This Row],[UTILIDAD POR PRODUCTO]] -> 2020
A11: A005 | B11: =IFERROR(VLOOKUP(INVENTARIO[[#This Row],[CODIGO]],BASEDEDATOS[],2,FALSE),"NO EXISTE") -> DETERGENTE CELESTE CON SUAVIZANTE DE 5 LITROS | C11: =IFERROR(VLOOKUP(INVENTARIO[[#This Row],[CODIGO]],BASEDEDATOS[],3,FALSE),"NO EXISTE") -> LAVANDERIA | D11: 60 | E11: 9 | F11: =INVENTARIO[[#This Row],[COMPRAS]]-INVENTARIO[[#This Row],[VENTAS]] -> 51 | G11: 1490 | H11: 2500 | I11: =INVENTARIO[[#This Row],[PRECIO DE VENTA]]-INVENTARIO[[#This Row],[COSTO UNITARIO]] -> 1010 | J11: =INVENTARIO[[#This Row],[COSTO UNITARIO]]*INVENTARIO[[#This Row],[STOCK]] -> 75990 | K11: =+INVENTARIO[[#This Row],[VENTAS]]*INVENTARIO[[#This Row],[UTILIDAD POR PRODUCTO]] -> 9090
A12: A006 | B12: =IFERROR(VLOOKUP(INVENTARIO[[#This Row],[CODIGO]],BASEDEDATOS[],2,FALSE),"NO EXISTE") -> DETERGENTE NARANJO CON SUAVIZANTE DE 5 LITROS | C12: =IFERROR(VLOOKUP(INVENTARIO[[#This Row],[CODIGO]],BASEDEDATOS[],3,FALSE),"NO EXISTE") -> LAVANDERIA | D12: 30 | E12: 2 | F12: =INVENTARIO[[#This Row],[COMPRAS]]-INVENTARIO[[#This Row],[VENTAS]] -> 28 | G12: 1490 | H12: 2500 | I12: =INVENTARIO[[#This Row],[PRECIO DE VENTA]]-INVENTARIO[[#This Row],[COSTO UNITARIO]] -> 1010 | J12: =INVENTARIO[[#This Row],[COSTO UNITARIO]]*INVENTARIO[[#This Row],[STOCK]] -> 41720 | K12: =+INVENTARIO[[#This Row],[VENTAS]]*INVENTARIO[[#This Row],[UTILIDAD POR PRODUCTO]] -> 2020
A13: A007 | B13: =IFERROR(VLOOKUP(INVENTARIO[[#This Row],[CODIGO]],BASEDEDATOS[],2,FALSE),"NO EXISTE") -> DETERGENTE ROSADO CON SUAVIZANTE DE 5 LITROS | C13: =IFERROR(VLOOKUP(INVENTARIO[[#This Row],[CODIGO]],BASEDEDATOS[],3,FALSE),"NO EXISTE") -> LAVANDERIA | D13: 40 | E13: 2 | F13: =INVENTARIO[[#This Row],[COMPRAS]]-INVENTARIO[[#This Row],[VENTAS]] -> 38 | G13: 1490 | H13: 2500 | I13: =INVENTARIO[[#This Row],[PRECIO DE VENTA]]-INVENTARIO[[#This Row],[COSTO UNITARIO]] -> 1010 | J13: =INVENTARIO[[#This Row],[COSTO UNITARIO]]*INVENTARIO[[#This Row],[STOCK]] -> 56620 | K13: =+INVENTARIO[[#This Row],[VENTAS]]*INVENTARIO[[#This Row],[UTILIDAD POR PRODUCTO]] -> 2020
A14: A008 | B14: =IFERROR(VLOOKUP(INVENTARIO[[#This Row],[CODIGO]],BASEDEDATOS[],2,FALSE),"NO EXISTE") -> DETERGENTE PREMIUM AROMA OMO DE 3 LITROS (PACK DE 4 UNID) | C14: =IFERROR(VLOOKUP(INVENTARIO[[#This Row],[CODIGO]],BASEDEDATOS[],3,FALSE),"NO EXISTE") -> LAVANDERIA | D14: 16 | E14: 16 | F14: =INVENTARIO[[#This Row],[COMPRAS]]-INVENTARIO[[#This Row],[VENTAS]] -> 0 | G14: 1350 | H14: 3000 | I14: =INVENTARIO[[#This Row],[PRECIO DE VENTA]]-INVENTARIO[[#This Row],[COSTO UNITARIO]] -> 1650 | J14: =INVENTARIO[[#This Row],[COSTO UNITARIO]]*INVENTARIO[[#This Row],[STOCK]] -> 0 | K14: =+INVENTARIO[[#This Row],[VENTAS]]*INVENTARIO[[#This Row],[UTILIDAD POR PRODUCTO]] -> 26400
A15: A009 | B15: =IFERROR(VLOOKUP(INVENTARIO[[#This Row],[CODIGO]],BASEDEDATOS[],2,FALSE),"NO EXISTE") -> DETERGENTE DE BEBÉ 3 LITROS | C15: =IFERROR(VLOOKUP(INVENTARIO[[#This Row],[CODIGO]],BASEDEDATOS[],3,FALSE),"NO EXISTE") -> LAVANDERIA | D15: 5 | E15: 2 | F15: =INVENTARIO[[#This Row],[COMPRAS]]-INVENTARIO[[#This Row],[VENTAS]] -> 3 | G15: 2450 | H15: 4000 | I15: =INVENTARIO[[#This Row],[PRECIO DE VENTA]]-INVENTARIO[[#This Row],[COSTO UNITARIO]] -> 1550 | J15: =INVENTARIO[[#This Row],[COSTO UNITARIO]]*INVENTARIO[[#This Row],[STOCK]] -> 7350 | K15: =+INVENTARIO[[#This Row],[VENTAS]]*INVENTARIO[[#This Row],[UTILIDAD POR PRODUCTO]] -> 3100
A16: A010 | B16: =IFERROR(VLOOKUP(INVENTARIO[[#This Row],[CODIGO]],BASEDEDATOS[],2,FALSE),"NO EXISTE") -> DETERGENTE OMO PARA DILUIR 3 LITROS | C16: =IFERROR(VLOOKUP(INVENTARIO[[#This Row],[CODIGO]],BASEDEDATOS[],3,FALSE),"NO EXISTE") -> LAVANDERIA | D16: 24 | E16: 11 | F16: =INVENTARIO[[#This Row],[COMPRAS]]-INVENTARIO[[#This Row],[VENTAS]] -> 13 | G16: 3490 | H16: 4500 | I16: =INVENTARIO[[#This Row],[PRECIO DE VENTA]]-INVENTARIO[[#This Row],[COSTO UNITARIO]] -> 1010 | J16: =INVENTARIO[[#This Row],[COSTO UNITARIO]]*INVENTARIO[[#This Row],[STOCK]] -> 45370 | K16: =+INVENTARIO[[#This Row],[VENTAS]]*INVENTARIO[[#This Row],[UTILIDAD POR PRODUCTO]] -> 11110
A17: A011 | B17: =IFERROR(VLOOKUP(INVENTARIO[[#This Row],[CODIGO]],BASEDEDATOS[],2,FALSE),"NO EXISTE") -> DETERGENTE OMO DE 400 ML | C17: =IFERROR(VLOOKUP(INVENTARIO[[#This Row],[CODIGO]],BASEDEDATOS[],3,FALSE),"NO EXISTE") -> LAVANDERIA | D17: 15 | E17: 3 | F17: =INVENTARIO[[#This Row],[COMPRAS]]-INVENTARIO[[#This Row],[VENTAS]] -> 12 | G17: 690 | H17: 1000 | I17: =INVENTARIO[[#This Row],[PRECIO DE VENTA]]-INVENTARIO[[#This Row],[COSTO UNITARIO]] -> 310 | J17: =INVENTARIO[[#This Row],[COSTO UNITARIO]]*INVENTARIO[[#This Row],[STOCK]] -> 8280 | K17: =+INVENTARIO[[#This Row],[VENTAS]]*INVENTARIO[[#This Row],[UTILIDAD POR PRODUCTO]] -> 930
A18: A012 | B18: =IFERROR(VLOOKUP(INVENTARIO[[#This Row],[CODIGO]],BASEDEDATOS[],2,FALSE),"NO EXISTE") -> DETERGENTE OMO LIQUIDO BIDÓN 3 LITROS | C18: =IFERROR(VLOOKUP(INVENTARIO[[#This Row],[CODIGO]],BASEDEDATOS[],3,FALSE),"NO EXISTE") -> LAVANDERIA | D18: 0 | E18: {=SUM(SUMIF(VENTAS[CODIGO],INVENTARIO!A17:A20,VENTAS[CANTIDAD]))} -> 0 | F18: =INVENTARIO[[#This Row],[COMPRAS]]-INVENTARIO[[#This Row],[VENTAS]] -> 0 | G18: 0 | H18: 0 | I18: =INVENTARIO[[#This Row],[PRECIO DE VENTA]]-INVENTARIO[[#This Row],[COSTO UNITARIO]] -> 0 | J18: =INVENTARIO[[#This Row],[COSTO UNITARIO]]*INVENTARIO[[#This Row],[STOCK]] -> 0 | K18: =+INVENTARIO[[#This Row],[VENTAS]]*INVENTARIO[[#This Row],[UTILIDAD POR PRODUCTO]] -> 0
A19: A013 | B19: =IFERROR(VLOOKUP(INVENTARIO[[#This Row],[CODIGO]],BASEDEDATOS[],2,FALSE),"NO EXISTE") -> DETERGENTE BIO KLINNING AZUL | C19: =IFERROR(VLOOKUP(INVENTARIO[[#This Row],[CODIGO]],BASEDEDATOS[],3,FALSE),"NO EXISTE") -> LAVANDERIA | D19: 16 | E19: 0 | F19: =INVENTARIO[[#This Row],[COMPRAS]]-INVENTARIO[[#This Row],[VENTAS]] -> 16 | G19: 950 | H19: 0 | I19: =INVENTARIO[[#This Row],[PRECIO DE VENTA]]-INVENTARIO[[#This Row],[COSTO UNITARIO]] -> -950 | J19: =INVENTARIO[[#This Row],[COSTO UNITARIO]]*INVENTARIO[[#This Row],[STOCK]] -> 15200 | K19: =+INVENTARIO[[#This Row],[VENTAS]]*INVENTARIO[[#This Row],[UTILIDAD POR PRODUCTO]] -> 0
A20: A014 | B20: =IFERROR(VLOOKUP(INVENTARIO[[#This Row],[CODIGO]],BASEDEDATOS[],2,FALSE),"NO EXISTE") -> DETERGENTE BIO KLINNING VERDE | C20: =IFERROR(VLOOKUP(INVENTARIO[[#This Row],[CODIGO]],BASEDEDATOS[],3,FALSE),"NO EXISTE") -> LAVANDERIA | D20: 16 | E20: {=SUM(SUMIF(VENTAS[CODIGO],INVENTARIO!A19:A22,VENTAS[CANTIDAD]))} -> 0 | F20: =INVENTARIO[[#This Row],[COMPRAS]]-INVENTARIO[[#This Row],[VENTAS]] -> 16 | G20: 950 | H20: 0 | I20: =INVENTARIO[[#This Row],[PRECIO DE VENTA]]-INVENTARIO[[#This Row],[COSTO UNITARIO]] -> -950 | J20: =INVENTARIO[[#This Row],[COSTO UNITARIO]]*INVENTARIO[[#This Row],[STOCK]] -> 15200 | K20: =+INVENTARIO[[#This Row],[VENTAS]]*INVENTARIO[[#This Row],[UTILIDAD POR PRODUCTO]] -> 0
A21: A015 | B21: =IFERROR(VLOOKUP(INVENTARIO[[#This Row],[CODIGO]],BASEDEDATOS[],2,FALSE),"NO EXISTE") -> DETERGENTE SOFT LIQUIDO BIDÓN DE 3 LITROS | C21: =IFERROR(VLOOKUP(INVENTARIO[[#This Row],[CODIGO]],BASEDEDATOS[],3,FALSE),"NO EXISTE") -> LAVANDERIA | D21: 0 | E21: {=SUM(SUMIF(VENTAS[CODIGO],INVENTARIO!A20:A23,VENTAS[CANTIDAD]))} -> 0 | F21: =INVENTARIO[[#This Row],[COMPRAS]]-INVENTARIO[[#This Row],[VENTAS]] -> 0 | G21: 0 | H21: 0 | I21: =INVENTARIO[[#This Row],[PRECIO DE VENTA]]-INVENTARIO[[#This Row],[COSTO UNITARIO]] -> 0 | J21: =INVENTARIO[[#This Row],[COSTO UNITARIO]]*INVENTARIO[[#This Row],[STOCK]] -> 0 | K21: =+INVENTARIO[[#This Row],[VENTAS]]*INVENTARIO[[#This Row],[UTILIDAD POR PRODUCTO]] -> 0
A22: A016 | B22: =IFERROR(VLOOKUP(INVENTARIO[[#This Row],[CODIGO]],BASEDEDATOS[],2,FALSE),"NO EXISTE") -> DETERGENTE EN POLVO QUITA MANCHA ROSADO | C22: =IFERROR(VLOOKUP(INVENTARIO[[#This Row],[CODIGO]],BASEDEDATOS[],3,FALSE),"NO EXISTE") -> LAVANDERIA | D22: 6 | E22: 2 | F22: =INVENTARIO[[#This Row],[COMPRAS]]-INVENTARIO[[#This Row],[VENTAS]] -> 4 | G22: 490 | H22: 1000 | I22: =INVENTARIO[[#This Row],[PRECIO DE VENTA]]-INVENTARIO[[#This Row],[COSTO UNITARIO]] -> 510 | J22: =INVENTARIO[[#This Row],[COSTO UNITARIO]]*INVENTARIO[[#This Row],[STOCK]] -> 1960 | K22: =+INVENTARIO[[#This Row],[VENTAS]]*INVENTARIO[[#This Row],[UTILIDAD POR PRODUCTO]] -> 1020
A23: A017 | B23: =IFERROR(VLOOKUP(INVENTARIO[[#This Row],[CODIGO]],BASEDEDATOS[],2,FALSE),"NO EXISTE") -> DETERGENTE EN POLVO QUITA MANCHA MORADO | C23: =IFERROR(VLOOKUP(INVENTARIO[[#This Row],[CODIGO]],BASEDEDATOS[],3,FALSE),"NO EXISTE") -> LAVANDERIA | D23: 6 | E23: 1 | F23: =INVENTARIO[[#This Row],[COMPRAS]]-INVENTARIO[[#This Row],[VENTAS]] -> 5 | G23: 490 | H23: 1000 | I23: =INVENTARIO[[#This Row],[PRECIO DE VENTA]]-INVENTARIO[[#This Row],[COSTO UNITARIO]] -> 510 | J23: =INVENTARIO[[#This Row],[COSTO UNITARIO]]*INVENTARIO[[#This Row],[STOCK]] -> 2450 | K23: =+INVENTARIO[[#This Row],[VENTAS]]*INVENTARIO[[#This Row],[UTILIDAD POR PRODUCTO]] -> 510
A24: A018 | B24: =IFERROR(VLOOKUP(INVENTARIO[[#This Row],[CODIGO]],BASEDEDATOS[],2,FALSE),"NO EXISTE") -> DETERGENTE EN POLVO VIRGINIA | C24: =IFERROR(VLOOKUP(INVENTARIO[[#This Row],[CODIGO]],BASEDEDATOS[],3,FALSE),"NO EXISTE") -> LAVANDERIA | D24: 18 | E24: 0 | F24: =INVENTARIO[[#This Row],[COMPRAS]]-INVENTARIO[[#This Row],[VENTAS]] -> 18 | G24: 890 | H24: 2000 | I24: =INVENTARIO[[#This Row],[PRECIO DE VENTA]]-INVENTARIO[[#This Row],[COSTO UNITARIO]] -> 1110 | J24: =INVENTARIO[[#This Row],[COSTO UNITARIO]]*INVENTARIO[[#This Row],[STOCK]] -> 16020 | K24: =+INVENTARIO[[#This Row],[VENTAS]]*INVENTARIO[[#This Row],[UTILIDAD POR PRODUCTO]] -> 0
A25: A019 | B25: =IFERROR(VLOOKUP(INVENTARIO[[#This Row],[CODIGO]],BASEDEDATOS[],2,FALSE),"NO EXISTE") -> CLORO ROPA BLANCA SPUM DE 1 LITRO | C25: =IFERROR(VLOOKUP(INVENTARIO[[#This Row],[CODIGO]],BASEDEDATOS[],3,FALSE),"NO EXISTE") -> LAVANDERIA | D25: 12 | E25: 4 | F25: =INVENTARIO[[#This Row],[COMPRAS]]-INVENTARIO[[#This Row],[VENTAS]] -> 8 | G25: 733 | H25: 1500 | I25: =INVENTARIO[[#This Row],[PRECIO DE VENTA]]-INVENTARIO[[#This Row],[COSTO UNITARIO]] -> 767 | J25: =INVENTARIO[[#This Row],[COSTO UNITARIO]]*INVENTARIO[[#This Row],[STOCK]] -> 5864 | K25: =+INVENTARIO[[#This Row],[VENTAS]]*INVENTARIO[[#This Row],[UTILIDAD POR PRODUCTO]] -> 3068
A26: A020 | B26: =IFERROR(VLOOKUP(INVENTARIO[[#This Row],[CODIGO]],BASEDEDATOS[],2,FALSE),"NO EXISTE") -> CLORO ROPA A COLOR SPUM DE 1 LITRO | C26: =IFERROR(VLOOKUP(INVENTARIO[[#This Row],[CODIGO]],BASEDEDATOS[],3,FALSE),"NO EXISTE") -> LAVANDERIA | D26: 24 | E26: 5 | F26: =INVENTARIO[[#This Row],[COMPRAS]]-INVENTARIO[[#This Row],[VENTAS]] -> 19 | G26: 666 | H26: 1500 | I26: =INVENTARIO[[#This Row],[PRECIO DE VENTA]]-INVENTARIO[[#This Row],[COSTO UNITARIO]] -> 834 | J26: =INVENTARIO[[#This Row],[COSTO UNITARIO]]*INVENTARIO[[#This Row],[STOCK]] -> 12654 | K26: =+INVENTARIO[[#This Row],[VENTAS]]*INVENTARIO[[#This Row],[UTILIDAD POR PRODUCTO]] -> 4170
A27: A021 | B27: =IFERROR(VLOOKUP(INVENTARIO[[#This Row],[CODIGO]],BASEDEDATOS[],2,FALSE),"NO EXISTE") -> VANISH BLANCO | C27: =IFERROR(VLOOKUP(INVENTARIO[[#This Row],[CODIGO]],BASEDEDATOS[],3,FALSE),"NO EXISTE") -> LAVANDERIA | D27: 12 | E27: 10 | F27: =INVENTARIO[[#This Row],[COMPRAS]]-INVENTARIO[[#This Row],[VENTAS]] -> 2 | G27: 303 | H27: 650 | I27: =INVENTARIO[[#This Row],[PRECIO DE VENTA]]-INVENTARIO[[#This Row],[COSTO UNITARIO]] -> 347 | J27: =INVENTARIO[[#This Row],[COSTO UNITARIO]]*INVENTARIO[[#This Row],[STOCK]] -> 606 | K27: =+INVENTARIO[[#This Row],[VENTAS]]*INVENTARIO[[#This Row],[UTILIDAD POR PRODUCTO]] -> 3470
A28: A022 | B28: =IFERROR(VLOOKUP(INVENTARIO[[#This Row],[CODIGO]],BASEDEDATOS[],2,FALSE),"NO EXISTE") -> VANISH ROSADO | C28: =IFERROR(VLOOKUP(INVENTARIO[[#This Row],[CODIGO]],BASEDEDATOS[],3,FALSE),"NO EXISTE") -> LAVANDERIA | D28: 12 | E28: 5 | F28: =INVENTARIO[[#This Row],[COMPRAS]]-INVENTARIO[[#This Row],[VENTAS]] -> 7 | G28: 303 | H28: 650 | I28: =INVENTARIO[[#This Row],[PRECIO DE VENTA]]-INVENTARIO[[#This Row],[COSTO UNITARIO]] -> 347 | J28: =INVENTARIO[[#This Row],[COSTO UNITARIO]]*INVENTARIO[[#This Row],[STOCK]] -> 2121 | K28: =+INVENTARIO[[#This Row],[VENTAS]]*INVENTARIO[[#This Row],[UTILIDAD POR PRODUCTO]] -> 1735
A29: A023 | B29: =IFERROR(VLOOKUP(INVENTARIO[[#This Row],[CODIGO]],BASEDEDATOS[],2,FALSE),"NO EXISTE") -> CLORO CONCENTRADO DE 5 LITROS | C29: =IFERROR(VLOOKUP(INVENTARIO[[#This Row],[CODIGO]],BASEDEDATOS[],3,FALSE),"NO EXISTE") -> DESINFECCIÓN | D29: 0 | E29: {=SUM(SUMIF(VENTAS[CODIGO],INVENTARIO!A28:A31,VENTAS[CANTIDAD]))} -> 0 | F29: =INVENTARIO[[#This Row],[COMPRAS]]-INVENTARIO[[#This Row],[VENTAS]] -> 0 | G29: 0 | H29: 0 | I29: =INVENTARIO[[#This Row],[PRECIO DE VENTA]]-INVENTARIO[[#This Row],[COSTO UNITARIO]] -> 0 | J29: =INVENTARIO[[#This Row],[COSTO UNITARIO]]*INVENTARIO[[#This Row],[STOCK]] -> 0 | K29: =+INVENTARIO[[#This Row],[VENTAS]]*INVENTARIO[[#This Row],[UTILIDAD POR PRODUCTO]] -> 0
A30: A024 | B30: =IFERROR(VLOOKUP(INVENTARIO[[#This Row],[CODIGO]],BASEDEDATOS[],2,FALSE),"NO EXISTE") -> CLORINDA DE 1 LITRO | C30: =IFERROR(VLOOKUP(INVENTARIO[[#This Row],[CODIGO]],BASEDEDATOS[],3,FALSE),"NO EXISTE") -> DESINFECCIÓN | D30: 0 | E30: {=SUM(SUMIF(VENTAS[CODIGO],INVENTARIO!A29:A32,VENTAS[CANTIDAD]))} -> 0 | F30: =INVENTARIO[[#This Row],[COMPRAS]]-INVENTARIO[[#This Row],[VENTAS]] -> 0 | G30: 0 | H30: 0 | I30: =INVENTARIO[[#This Row],[PRECIO DE VENTA]]-INVENTARIO[[#This Row],[COSTO UNITARIO]] -> 0 | J30: =INVENTARIO[[#This Row],[COSTO UNITARIO]]*INVENTARIO[[#This Row],[STOCK]] -> 0 | K30: =+INVENTARIO[[#This Row],[VENTAS]]*INVENTARIO[[#This Row],[UTILIDAD POR PRODUCTO]] -> 0
A31: A025 | B31: =IFERROR(VLOOKUP(INVENTARIO[[#This Row],[CODIGO]],BASEDEDATOS[],2,FALSE),"NO EXISTE") -> CLORO GEL CLOROX | C31: =IFERROR(VLOOKUP(INVENTARIO[[#This Row],[CODIGO]],BASEDEDATOS[],3,FALSE),"NO EXISTE") -> DESINFECCIÓN | D31: 0 | E31: 0 | F31: =INVENTARIO[[#This Row],[COMPRAS]]-INVENTARIO[[#This Row],[VENTAS]] -> 0 | G31: 0 | H31: 0 | I31: =INVENTARIO[[#This Row],[PRECIO DE VENTA]]-INVENTARIO[[#This Row],[COSTO UNITARIO]] -> 0 | J31: =INVENTARIO[[#This Row],[COSTO UNITARIO]]*INVENTARIO[[#This Row],[STOCK]] -> 0 | K31: =+INVENTARIO[[#This Row],[VENTAS]]*INVENTARIO[[#This Row],[UTILIDAD POR PRODUCTO]] -> 0
A32: A026 | B32: =IFERROR(VLOOKUP(INVENTARIO[[#This Row],[CODIGO]],BASEDEDATOS[],2,FALSE),"NO EXISTE") -> CLORO IGENIX LIQUIDO | C32: =IFERROR(VLOOKUP(INVENTARIO[[#This Row],[CODIGO]],BASEDEDATOS[],3,FALSE),"NO EXISTE") -> DESINFECCIÓN | D32: 12 | E32: 2 | F32: =INVENTARIO[[#This Row],[COMPRAS]]-INVENTARIO[[#This Row],[VENTAS]] -> 10 | G32: 690 | H32: 1000 | I32: =INVENTARIO[[#This Row],[PRECIO DE VENTA]]-INVENTARIO[[#This Row],[COSTO UNITARIO]] -> 310 | J32: =INVENTARIO[[#This Row],[COSTO UNITARIO]]*INVENTARIO[[#This Row],[STOCK]] -> 6900 | K32: =+INVENTARIO[[#This Row],[VENTAS]]*INVENTARIO[[#This Row],[UTILIDAD POR PRODUCTO]] -> 620
A33: A027 | B33: =IFERROR(VLOOKUP(INVENTARIO[[#This Row],[CODIGO]],BASEDEDATOS[],2,FALSE),"NO EXISTE") -> CLORINDA CLORO GEL | C33: =IFERROR(VLOOKUP(INVENTARIO[[#This Row],[CODIGO]],BASEDEDATOS[],3,FALSE),"NO EXISTE") -> DESINFECCIÓN | D33: 24 | E33: 5 | F33: =INVENTARIO[[#This Row],[COMPRAS]]-INVENTARIO[[#This Row],[VENTAS]] -> 19 | G33: 1050 | H33: 1900 | I33: =INVENTARIO[[#This Row],[PRECIO DE VENTA]]-INVENTARIO[[#This Row],[COSTO UNITARIO]] -> 850 | J33: =INVENTARIO[[#This Row],[COSTO UNITARIO]]*INVENTARIO[[#This Row],[STOCK]] -> 19950 | K33: =+INVENTARIO[[#This Row],[VENTAS]]*INVENTARIO[[#This Row],[UTILIDAD POR PRODUCTO]] -> 4250
A34: A028 | B34: =IFERROR(VLOOKUP(INVENTARIO[[#This Row],[CODIGO]],BASEDEDATOS[],2,FALSE),"NO EXISTE") -> CLORINDA CLORO GEL EXCEL MORADO | C34: =IFERROR(VLOOKUP(INVENTARIO[[#This Row],[CODIGO]],BASEDEDATOS[],3,FALSE),"NO EXISTE") -> DESINFECCIÓN | D34: 12 | E34: 0 | F34: =INVENTARIO[[#This Row],[COMPRAS]]-INVENTARIO[[#This Row],[VENTAS]] -> 12 | G34: 797 | H34: 1300 | I34: =INVENTARIO[[#This Row],[PRECIO DE VENTA]]-INVENTARIO[[#This Row],[COSTO UNITARIO]] -> 503 | J34: =INVENTARIO[[#This Row],[COSTO UNITARIO]]*INVENTARIO[[#This Row],[STOCK]] -> 9564 | K34: =+INVENTARIO[[#This Row],[VENTAS]]*INVENTARIO[[#This Row],[UTILIDAD POR PRODUCTO]] -> 0
A35: A029 | B35: =IFERROR(VLOOKUP(INVENTARIO[[#This Row],[CODIGO]],BASEDEDATOS[],2,FALSE),"NO EXISTE") -> CLORINDA CLORO GEL EXCEL AMARILLO | C35: =IFERROR(VLOOKUP(INVENTARIO[[#This Row],[CODIGO]],BASEDEDATOS[],3,FALSE),"NO EXISTE") -> DESINFECCIÓN | D35: 12 | E35: 2 | F35: =INVENTARIO[[#This Row],[COMPRAS]]-INVENTARIO[[#This Row],[VENTAS]] -> 10 | G35: 797 | H35: 1300 | I35: =INVENTARIO[[#This Row],[PRECIO DE VENTA]]-INVENTARIO[[#This Row],[COSTO UNITARIO]] -> 503 | J35: =INVENTARIO[[#This Row],[COSTO UNITARIO]]*INVENTARIO[[#This Row],[STOCK]] -> 7970 | K35: =+INVENTARIO[[#This Row],[VENTAS]]*INVENTARIO[[#This Row],[UTILIDAD POR PRODUCTO]] -> 1006
A36: A030 | B36: =IFERROR(VLOOKUP(INVENTARIO[[#This Row],[CODIGO]],BASEDEDATOS[],2,FALSE),"NO EXISTE") -> ANTIGRASA SPUM DE 2 LITROS | C36: =IFERROR(VLOOKUP(INVENTARIO[[#This Row],[CODIGO]],BASEDEDATOS[],3,FALSE),"NO EXISTE") -> COCINA | D36: 10 | E36: 2 | F36: =INVENTARIO[[#This Row],[COMPRAS]]-INVENTARIO[[#This Row],[VENTAS]] -> 8 | G36: 1049 | H36: 2000 | I36: =INVENTARIO[[#This Row],[PRECIO DE VENTA]]-INVENTARIO[[#This Row],[COSTO UNITARIO]] -> 951 | J36: =INVENTARIO[[#This Row],[COSTO UNITARIO]]*INVENTARIO[[#This Row],[STOCK]] -> 8392 | K36: =+INVENTARIO[[#This Row],[VENTAS]]*INVENTARIO[[#This Row],[UTILIDAD POR PRODUCTO]] -> 1902
A37: A031 | B37: =IFERROR(VLOOKUP(INVENTARIO[[#This Row],[CODIGO]],BASEDEDATOS[],2,FALSE),"NO EXISTE") -> ANTIGRASA SPUM DE 500 ML | C37: =IFERROR(VLOOKUP(INVENTARIO[[#This Row],[CODIGO]],BASEDEDATOS[],3,FALSE),"NO EXISTE") -> COCINA | D37: 12 | E37: 6 | F37: =INVENTARIO[[#This Row],[COMPRAS]]-INVENTARIO[[#This Row],[VENTAS]] -> 6 | G37: 700 | H37: 1400 | I37: =INVENTARIO[[#This Row],[PRECIO DE VENTA]]-INVENTARIO[[#This Row],[COSTO UNITARIO]] -> 700 | J37: =INVENTARIO[[#This Row],[COSTO UNITARIO]]*INVENTARIO[[#This Row],[STOCK]] -> 4200 | K37: =+INVENTARIO[[#This Row],[VENTAS]]*INVENTARIO[[#This Row],[UTILIDAD POR PRODUCTO]] -> 4200
A38: A032 | B38: =IFERROR(VLOOKUP(INVENTARIO[[#This Row],[CODIGO]],BASEDEDATOS[],2,FALSE),"NO EXISTE") -> SACASARRO SPUM DE 2 LITROS | C38: =IFERROR(VLOOKUP(INVENTARIO[[#This Row],[CODIGO]],BASEDEDATOS[],3,FALSE),"NO EXISTE") -> COCINA | D38: 9 | E38: 2 | F38: =INVENTARIO[[#This Row],[COMPRAS]]-INVENTARIO[[#This Row],[VENTAS]] -> 7 | G38: 888 | H38: 2300 | I38: =INVENTARIO[[#This Row],[PRECIO DE VENTA]]-INVENTARIO[[#This Row],[COSTO UNITARIO]] -> 1412 | J38: =INVENTARIO[[#This Row],[COSTO UNITARIO]]*INVENTARIO[[#This Row],[STOCK]] -> 6216 | K38: =+INVENTARIO[[#This Row],[VENTAS]]*INVENTARIO[[#This Row],[UTILIDAD POR PRODUCTO]] -> 2824
A39: A033 | B39: =IFERROR(VLOOKUP(INVENTARIO[[#This Row],[CODIGO]],BASEDEDATOS[],2,FALSE),"NO EXISTE") -> SACASARRO SPUM DE 500 ML | C39: =IFERROR(VLOOKUP(INVENTARIO[[#This Row],[CODIGO]],BASEDEDATOS[],3,FALSE),"NO EXISTE") -> COCINA | D39: 10 | E39: 0 | F39: =INVENTARIO[[#This Row],[COMPRAS]]-INVENTARIO[[#This Row],[VENTAS]] -> 10 | G39: 970 | H39: 2000 | I39: =INVENTARIO[[#This Row],[PRECIO DE VENTA]]-INVENTARIO[[#This Row],[COSTO UNITARIO]] -> 1030 | J39: =INVENTARIO[[#This Row],[COSTO UNITARIO]]*INVENTARIO[[#This Row],[STOCK]] -> 9700 | K39: =+INVENTARIO[[#This Row],[VENTAS]]*INVENTARIO[[#This Row],[UTILIDAD POR PRODUCTO]] -> 0
A40: A034 | B40: =IFERROR(VLOOKUP(INVENTARIO[[#This Row],[CODIGO]],BASEDEDATOS[],2,FALSE),"NO EXISTE") -> LAVALOSA SPUM DE 1 LITRO | C40: =IFERROR(VLOOKUP(INVENTARIO[[#This Row],[CODIGO]],BASEDEDATOS[],3,FALSE),"NO EXISTE") -> COCINA | D40: 12 | E40: 2 | F40: =INVENTARIO[[#This Row],[COMPRAS]]-INVENTARIO[[#This Row],[VENTAS]] -> 10 | G40: 650 | H40: 1400 | I40: =INVENTARIO[[#This Row],[PRECIO DE VENTA]]-INVENTARIO[[#This Row],[COSTO UNITARIO]] -> 750 | J40: =INVENTARIO[[#This Row],[COSTO UNITARIO]]*INVENTARIO[[#This Row],[STOCK]] -> 6500 | K40: =+INVENTARIO[[#This Row],[VENTAS]]*INVENTARIO[[#This Row],[UTILIDAD POR PRODUCTO]] -> 1500
A41: A035 | B41: =IFERROR(VLOOKUP(INVENTARIO[[#This Row],[CODIGO]],BASEDEDATOS[],2,FALSE),"NO EXISTE") -> LAVALOSA SPUM DE 2 LITROS | C41: =IFERROR(VLOOKUP(INVENTARIO[[#This Row],[CODIGO]],BASEDEDATOS[],3,FALSE),"NO EXISTE") -> COCINA | D41: 9 | E41: 3 | F41: =INVENTARIO[[#This Row],[COMPRAS]]-INVENTARIO[[#This Row],[VENTAS]] -> 6 | G41: 1010 | H41: 2300 | I41: =INVENTARIO[[#This Row],[PRECIO DE VENTA]]-INVENTARIO[[#This Row],[COSTO UNITARIO]] -> 1290 | J41: =INVENTARIO[[#This Row],[COSTO UNITARIO]]*INVENTARIO[[#This Row],[STOCK]] -> 6060 | K41: =+INVENTARIO[[#This Row],[VENTAS]]*INVENTARIO[[#This Row],[UTILIDAD POR PRODUCTO]] -> 3870
A42: A036 | B42: =IFERROR(VLOOKUP(INVENTARIO[[#This Row],[CODIGO]],BASEDEDATOS[],2,FALSE),"NO EXISTE") -> LAVALOSA SPUM DE 5 LITROS | C42: =IFERROR(VLOOKUP(INVENTARIO[[#This Row],[CODIGO]],BASEDEDATOS[],3,FALSE),"NO EXISTE") -> COCINA | D42: 10 | E42: 0 | F42: =INVENTARIO[[#This Row],[COMPRAS]]-INVENTARIO[[#This Row],[VENTAS]] -> 10 | G42: 2300 | H42: 4000 | I42: =INVENTARIO[[#This Row],[PRECIO DE VENTA]]-INVENTARIO[[#This Row],[COSTO UNITARIO]] -> 1700 | J42: =INVENTARIO[[#This Row],[COSTO UNITARIO]]*INVENTARIO[[#This Row],[STOCK]] -> 23000 | K42: =+INVENTARIO[[#This Row],[VENTAS]]*INVENTARIO[[#This Row],[UTILIDAD POR PRODUCTO]] -> 0
...

Sheet COMPRAS
A1: COMPRAS
I4: TOTAL
I5: =SUBTOTAL(9,I7:I118) -> 973059
A6: CODIGO | B6: FECHA | C6: MES | D6: AÑO | E6: NOMBRE DEL PRODUCTO | F6: CATEGORIA | G6: COSTO UNITARIO | H6: CANTIDAD | I6: TOTAL
A7: A001 | B7: 45945 | C7: =TEXT(COMPRAS[[#This Row],[FECHA]],"[$-es-CL]mmmm") -> octubre | D7: {=YEAR(IF(ISNUMBER(COMPRAS[[#This Row],[FECHA]]),COMPRAS[[#This Row],[FECHA]],FECHA.VALOR(COMPRAS[[#This Row],[FECHA]])))} -> 2025 | E7: =IFERROR(VLOOKUP(COMPRAS[[#This Row],[CODIGO]],INVENTARIO[],2,FALSE),"NO EXISTE") -> DETERGENTE BIO AZUL DE 5 LITROS | F7: =IFERROR(VLOOKUP(COMPRAS[[#This Row],[CODIGO]],INVENTARIO[],3,FALSE),"NO EXISTE") -> LAVANDERIA | G7: 920 | H7: 150 | I7: =COMPRAS[[#This Row],[COSTO UNITARIO]]*COMPRAS[[#This Row],[CANTIDAD]] -> 138000
A8: A002 | B8: 45945 | C8: =TEXT(COMPRAS[[#This Row],[FECHA]],"[$-es-CL]mmmm") -> octubre | D8: {=YEAR(IF(ISNUMBER(COMPRAS[[#This Row],[FECHA]]),COMPRAS[[#This Row],[FECHA]],FECHA.VALOR(COMPRAS[[#This Row],[FECHA]])))} -> 2025 | E8: =IFERROR(VLOOKUP(COMPRAS[[#This Row],[CODIGO]],INVENTARIO[],2,FALSE),"NO EXISTE") -> DETERGENTE BIO VERDE DE 5 LITROS | F8: =IFERROR(VLOOKUP(COMPRAS[[#This Row],[CODIGO]],INVENTARIO[],3,FALSE),"NO EXISTE") -> LAVANDERIA | G8: 920 | H8: 50 | I8: =COMPRAS[[#This Row],[COSTO UNITARIO]]*COMPRAS[[#This Row],[CANTIDAD]] -> 46000
A9: A003 | B9: 45945 | C9: =TEXT(COMPRAS[[#This Row],[FECHA]],"[$-es-CL]mmmm") -> octubre | D9: {=YEAR(IF(ISNUMBER(COMPRAS[[#This Row],[FECHA]]),COMPRAS[[#This Row],[FECHA]],FECHA.VALOR(COMPRAS[[#This Row],[FECHA]])))} -> 2025 | E9: =IFERROR(VLOOKUP(COMPRAS[[#This Row],[CODIGO]],INVENTARIO[],2,FALSE),"NO EXISTE") -> DETERGENTE MORADO CON SUAVIZANTE DE 5 LITROS | F9: =IFERROR(VLOOKUP(COMPRAS[[#This Row],[CODIGO]],INVENTARIO[],3,FALSE),"NO EXISTE") -> LAVANDERIA | G9: 1490 | H9: 0 | I9: =COMPRAS[[#This Row],[COSTO UNITARIO]]*COMPRAS[[#This Row],[CANTIDAD]] -> 0
A10: A004 | B10: 45945 | C10: =TEXT(COMPRAS[[#This Row],[FECHA]],"[$-es-CL]mmmm") -> octubre | D10: {=YEAR(IF(ISNUMBER(COMPRAS[[#This Row],[FECHA]]),COMPRAS[[#This Row],[FECHA]],FECHA.VALOR(COMPRAS[[#This Row],[FECHA]])))} -> 2025 | E10: =IFERROR(VLOOKUP(COMPRAS[[#This Row],[CODIGO]],INVENTARIO[],2,FALSE),"NO EXISTE") -> DETERGENTE BLANCO CON SUAVIZANTE DE 5 LITROS | F10: =IFERROR(VLOOKUP(COMPRAS[[#This Row],[CODIGO]],INVENTARIO[],3,FALSE),"NO EXISTE") -> LAVANDERIA | G10: 1490 | H10: 0 | I10: =COMPRAS[[#This Row],[COSTO UNITARIO]]*COMPRAS[[#This Row],[CANTIDAD]] -> 0
A11: A005 | B11: 45945 | C11: =TEXT(COMPRAS[[#This Row],[FECHA]],"[$-es-CL]mmmm") -> octubre | D11: {=YEAR(IF(ISNUMBER(COMPRAS[[#This Row],[FECHA]]),COMPRAS[[#This Row],[FECHA]],FECHA.VALOR(COMPRAS[[#This Row],[FECHA]])))} -> 2025 | E11: =IFERROR(VLOOKUP(COMPRAS[[#This Row],[CODIGO]],INVENTARIO[],2,FALSE),"NO EXISTE") -> DETERGENTE CELESTE CON SUAVIZANTE DE 5 LITROS | F11: =IFERROR(VLOOKUP(COMPRAS[[#This Row],[CODIGO]],INVENTARIO[],3,FALSE),"NO EXISTE") -> LAVANDERIA | G11: 1490 | I11: =COMPRAS[[#This Row],[COSTO UNITARIO]]*COMPRAS[[#This Row],[CANTIDAD]] -> 0
A12: A006 | B12: 45945 | C12: =TEXT(COMPRAS[[#This Row],[FECHA]],"[$-es-CL]mmmm") -> octubre | D12: {=YEAR(IF(ISNUMBER(COMPRAS[[#This Row],[FECHA]]),COMPRAS[[#This Row],[FECHA]],FECHA.VALOR(COMPRAS[[#This Row],[FECHA]])))} -> 2025 | E12: =IFERROR(VLOOKUP(COMPRAS[[#This Row],[CODIGO]],INVENTARIO[],2,FALSE),"NO EXISTE") -> DETERGENTE NARANJO CON SUAVIZANTE DE 5 LITROS | F12: =IFERROR(VLOOKUP(COMPRAS[[#This Row],[CODIGO]],INVENTARIO[],3,FALSE),"NO EXISTE") -> LAVANDERIA | G12: 1490 | I12: =COMPRAS[[#This Row],[COSTO UNITARIO]]*COMPRAS[[#This Row],[CANTIDAD]] -> 0
A13: A007 | B13: 45945 | C13: =TEXT(COMPRAS[[#This Row],[FECHA]],"[$-es-CL]mmmm") -> octubre | D13: {=YEAR(IF(ISNUMBER(COMPRAS[[#This Row],[FECHA]]),COMPRAS[[#This Row],[FECHA]],FECHA.VALOR(COMPRAS[[#This Row],[FECHA]])))} -> 2025 | E13: =IFERROR(VLOOKUP(COMPRAS[[#This Row],[CODIGO]],INVENTARIO[],2,FALSE),"NO EXISTE") -> DETERGENTE ROSADO CON SUAVIZANTE DE 5 LITROS | F13: =IFERROR(VLOOKUP(COMPRAS[[#This Row],[CODIGO]],INVENTARIO[],3,FALSE),"NO EXISTE") -> LAVANDERIA | G13: 1490 | I13: =COMPRAS[[#This Row],[COSTO UNITARIO]]*COMPRAS[[#This Row],[CANTIDAD]] -> 0
A14: A008 | B14: 45945 | C14: =TEXT(COMPRAS[[#This Row],[FECHA]],"[$-es-CL]mmmm") -> octubre | D14: {=YEAR(IF(ISNUMBER(COMPRAS[[#This Row],[FECHA]]),COMPRAS[[#This Row],[FECHA]],FECHA.VALOR(COMPRAS[[#This Row],[FECHA]])))} -> 2025 | E14: =IFERROR(VLOOKUP(COMPRAS[[#This Row],[CODIGO]],INVENTARIO[],2,FALSE),"NO EXISTE") -> DETERGENTE PREMIUM AROMA OMO DE 3 LITROS (PACK DE 4 UNID) | F14: =IFERROR(VLOOKUP(COMPRAS[[#This Row],[CODIGO]],INVENTARIO[],3,FALSE),"NO EXISTE") -> LAVANDERIA | G14: 1350 | I14: =COMPRAS[[#This Row],[COSTO UNITARIO]]*COMPRAS[[#This Row],[CANTIDAD]] -> 0
A15: A009 | B15: 45945 | C15: =TEXT(COMPRAS[[#This Row],[FECHA]],"[$-es-CL]mmmm") -> octubre | D15: {=YEAR(IF(ISNUMBER(COMPRAS[[#This Row],[FECHA]]),COMPRAS[[#This Row],[FECHA]],FECHA.VALOR(COMPRAS[[#This Row],[FECHA]])))} -> 2025 | E15: =IFERROR(VLOOKUP(COMPRAS[[#This Row],[CODIGO]],INVENTARIO[],2,FALSE),"NO EXISTE") -> DETERGENTE DE BEBÉ 3 LITROS | F15: =IFERROR(VLOOKUP(COMPRAS[[#This Row],[CODIGO]],INVENTARIO[],3,FALSE),"NO EXISTE") -> LAVANDERIA | G15: 2450 | H15: 4 | I15: =COMPRAS[[#This Row],[COSTO UNITARIO]]*COMPRAS[[#This Row],[CANTIDAD]] -> 9800
A16: A010 | B16: 45945 | C16: =TEXT(COMPRAS[[#This Row],[FECHA]],"[$-es-CL]mmmm") -> octubre | D16: {=YEAR(IF(ISNUMBER(COMPRAS[[#This Row],[FECHA]]),COMPRAS[[#This Row],[FECHA]],FECHA.VALOR(COMPRAS[[#This Row],[FECHA]])))} -> 2025 | E16: =IFERROR(VLOOKUP(COMPRAS[[#This Row],[CODIGO]],INVENTARIO[],2,FALSE),"NO EXISTE") -> DETERGENTE OMO PARA DILUIR 3 LITROS | F16: =IFERROR(VLOOKUP(COMPRAS[[#This Row],[CODIGO]],INVENTARIO[],3,FALSE),"NO EXISTE") -> LAVANDERIA | G16: 981 | H16: 50 | I16: =COMPRAS[[#This Row],[COSTO UNITARIO]]*COMPRAS[[#This Row],[CANTIDAD]] -> 49050
A17: A011 | B17: 45945 | C17: =TEXT(COMPRAS[[#This Row],[FECHA]],"[$-es-CL]mmmm") -> octubre | D17: {=YEAR(IF(ISNUMBER(COMPRAS[[#This Row],[FECHA]]),COMPRAS[[#This Row],[FECHA]],FECHA.VALOR(COMPRAS[[#This Row],[FECHA]])))} -> 2025 | E17: =IFERROR(VLOOKUP(COMPRAS[[#This Row],[CODIGO]],INVENTARIO[],2,FALSE),"NO EXISTE") -> DETERGENTE OMO DE 400 ML | F17: =IFERROR(VLOOKUP(COMPRAS[[#This Row],[CODIGO]],INVENTARIO[],3,FALSE),"NO EXISTE") -> LAVANDERIA | G17: 733 | H17: 12 | I17: =COMPRAS[[#This Row],[COSTO UNITARIO]]*COMPRAS[[#This Row],[CANTIDAD]] -> 8796
A18: A012 | B18: 45945 | C18: =TEXT(COMPRAS[[#This Row],[FECHA]],"[$-es-CL]mmmm") -> octubre | D18: {=YEAR(IF(ISNUMBER(COMPRAS[[#This Row],[FECHA]]),COMPRAS[[#This Row],[FECHA]],FECHA.VALOR(COMPRAS[[#This Row],[FECHA]])))} -> 2025 | E18: =IFERROR(VLOOKUP(COMPRAS[[#This Row],[CODIGO]],INVENTARIO[],2,FALSE),"NO EXISTE") -> DETERGENTE OMO LIQUIDO BIDÓN 3 LITROS | F18: =IFERROR(VLOOKUP(COMPRAS[[#This Row],[CODIGO]],INVENTARIO[],3,FALSE),"NO EXISTE") -> LAVANDERIA | G18: 733 | H18: 24 | I18: =COMPRAS[[#This Row],[COSTO UNITARIO]]*COMPRAS[[#This Row],[CANTIDAD]] -> 17592
A19: A013 | B19: 45945 | C19: =TEXT(COMPRAS[[#This Row],[FECHA]],"[$-es-CL]mmmm") -> octubre | D19: {=YEAR(IF(ISNUMBER(COMPRAS[[#This Row],[FECHA]]),COMPRAS[[#This Row],[FECHA]],FECHA.VALOR(COMPRAS[[#This Row],[FECHA]])))} -> 2025 | E19: =IFERROR(VLOOKUP(COMPRAS[[#This Row],[CODIGO]],INVENTARIO[],2,FALSE),"NO EXISTE") -> DETERGENTE BIO KLINNING AZUL | F19: =IFERROR(VLOOKUP(COMPRAS[[#This Row],[CODIGO]],INVENTARIO[],3,FALSE),"NO EXISTE") -> LAVANDERIA | G19: 990 | H19: 15 | I19: =COMPRAS[[#This Row],[COSTO UNITARIO]]*COMPRAS[[#This Row],[CANTIDAD]] -> 14850
A20: A014 | B20: 45945 | C20: =TEXT(COMPRAS[[#This Row],[FECHA]],"[$-es-CL]mmmm") -> octubre | D20: {=YEAR(IF(ISNUMBER(COMPRAS[[#This Row],[FECHA]]),COMPRAS[[#This Row],[FECHA]],FECHA.VALOR(COMPRAS[[#This Row],[FECHA]])))} -> 2025 | E20: =IFERROR(VLOOKUP(COMPRAS[[#This Row],[CODIGO]],INVENTARIO[],2,FALSE),"NO EXISTE") -> DETERGENTE BIO KLINNING VERDE | F20: =IFERROR(VLOOKUP(COMPRAS[[#This Row],[CODIGO]],INVENTARIO[],3,FALSE),"NO EXISTE") -> LAVANDERIA | G20: 720 | H20: 10 | I20: =COMPRAS[[#This Row],[COSTO UNITARIO]]*COMPRAS[[#This Row],[CANTIDAD]] -> 7200
A21: A015 | B21: 45945 | C21: =TEXT(COMPRAS[[#This Row],[FECHA]],"[$-es-CL]mmmm") -> octubre | D21: {=YEAR(IF(ISNUMBER(COMPRAS[[#This Row],[FECHA]]),COMPRAS[[#This Row],[FECHA]],FECHA.VALOR(COMPRAS[[#This Row],[FECHA]])))} -> 2025 | E21: =IFERROR(VLOOKUP(COMPRAS[[#This Row],[CODIGO]],INVENTARIO[],2,FALSE),"NO EXISTE") -> DETERGENTE SOFT LIQUIDO BIDÓN DE 3 LITROS | F21: =IFERROR(VLOOKUP(COMPRAS[[#This Row],[CODIGO]],INVENTARIO[],3,FALSE),"NO EXISTE") -> LAVANDERIA | G21: 833 | H21: 9 | I21: =COMPRAS[[#This Row],[COSTO UNITARIO]]*COMPRAS[[#This Row],[CANTIDAD]] -> 7497
A22: A016 | B22: 45945 | C22: =TEXT(COMPRAS[[#This Row],[FECHA]],"[$-es-CL]mmmm") -> octubre | D22: {=YEAR(IF(ISNUMBER(COMPRAS[[#This Row],[FECHA]]),COMPRAS[[#This Row],[FECHA]],FECHA.VALOR(COMPRAS[[#This Row],[FECHA]])))} -> 2025 | E22: =IFERROR(VLOOKUP(COMPRAS[[#This Row],[CODIGO]],INVENTARIO[],2,FALSE),"NO EXISTE") -> DETERGENTE EN POLVO QUITA MANCHA ROSADO | F22: =IFERROR(VLOOKUP(COMPRAS[[#This Row],[CODIGO]],INVENTARIO[],3,FALSE),"NO EXISTE") -> LAVANDERIA | G22: 1010 | H22: 10 | I22: =COMPRAS[[#This Row],[COSTO UNITARIO]]*COMPRAS[[#This Row],[CANTIDAD]] -> 10100
A23: A017 | B23: 45945 | C23: =TEXT(COMPRAS[[#This Row],[FECHA]],"[$-es-CL]mmmm") -> octubre | D23: {=YEAR(IF(ISNUMBER(COMPRAS[[#This Row],[FECHA]]),COMPRAS[[#This Row],[FECHA]],FECHA.VALOR(COMPRAS[[#This Row],[FECHA]])))} -> 2025 | E23: =IFERROR(VLOOKUP(COMPRAS[[#This Row],[CODIGO]],INVENTARIO[],2,FALSE),"NO EXISTE") -> DETERGENTE EN POLVO QUITA MANCHA MORADO | F23: =IFERROR(VLOOKUP(COMPRAS[[#This Row],[CODIGO]],INVENTARIO[],3,FALSE),"NO EXISTE") -> LAVANDERIA | G23: 1333 | H23: 9 | I23: =COMPRAS[[#This Row],[COSTO UNITARIO]]*COMPRAS[[#This Row],[CANTIDAD]] -> 11997
A24: A018 | B24: 45945 | C24: =TEXT(COMPRAS[[#This Row],[FECHA]],"[$-es-CL]mmmm") -> octubre | D24: {=YEAR(IF(ISNUMBER(COMPRAS[[#This Row],[FECHA]]),COMPRAS[[#This Row],[FECHA]],FECHA.VALOR(COMPRAS[[#This Row],[FECHA]])))} -> 2025 | E24: =IFERROR(VLOOKUP(COMPRAS[[#This Row],[CODIGO]],INVENTARIO[],2,FALSE),"NO EXISTE") -> DETERGENTE EN POLVO VIRGINIA | F24: =IFERROR(VLOOKUP(COMPRAS[[#This Row],[CODIGO]],INVENTARIO[],3,FALSE),"NO EXISTE") -> LAVANDERIA | G24: 990 | H24: 9 | I24: =COMPRAS[[#This Row],[COSTO UNITARIO]]*COMPRAS[[#This Row],[CANTIDAD]] -> 8910
A25: A019 | B25: 45945 | C25: =TEXT(COMPRAS[[#This Row],[FECHA]],"[$-es-CL]mmmm") -> octubre | D25: {=YEAR(IF(ISNUMBER(COMPRAS[[#This Row],[FECHA]]),COMPRAS[[#This Row],[FECHA]],FECHA.VALOR(COMPRAS[[#This Row],[FECHA]])))} -> 2025 | E25: =IFERROR(VLOOKUP(COMPRAS[[#This Row],[CODIGO]],INVENTARIO[],2,FALSE),"NO EXISTE") -> CLORO ROPA BLANCA SPUM DE 1 LITRO | F25: =IFERROR(VLOOKUP(COMPRAS[[#This Row],[CODIGO]],INVENTARIO[],3,FALSE),"NO EXISTE") -> LAVANDERIA | G25: 1049 | H25: 10 | I25: =COMPRAS[[#This Row],[COSTO UNITARIO]]*COMPRAS[[#This Row],[CANTIDAD]] -> 10490
A26: A020 | B26: 45945 | C26: =TEXT(COMPRAS[[#This Row],[FECHA]],"[$-es-CL]mmmm") -> octubre | D26: {=YEAR(IF(ISNUMBER(COMPRAS[[#This Row],[FECHA]]),COMPRAS[[#This Row],[FECHA]],FECHA.VALOR(COMPRAS[[#This Row],[FECHA]])))} -> 2025 | E26: =IFERROR(VLOOKUP(COMPRAS[[#This Row],[CODIGO]],INVENTARIO[],2,FALSE),"NO EXISTE") -> CLORO ROPA A COLOR SPUM DE 1 LITRO | F26: =IFERROR(VLOOKUP(COMPRAS[[#This Row],[CODIGO]],INVENTARIO[],3,FALSE),"NO EXISTE") -> LAVANDERIA | I26: =COMPRAS[[#This Row],[COSTO UNITARIO]]*COMPRAS[[#This Row],[CANTIDAD]] -> 0
A27: A021 | B27: 45945 | C27: =TEXT(COMPRAS[[#This Row],[FECHA]],"[$-es-CL]mmmm") -> octubre | D27: {=YEAR(IF(ISNUMBER(COMPRAS[[#This Row],[FECHA]]),COMPRAS[[#This Row],[FECHA]],FECHA.VALOR(COMPRAS[[#This Row],[FECHA]])))} -> 2025 | E27: =IFERROR(VLOOKUP(COMPRAS[[#This Row],[CODIGO]],INVENTARIO[],2,FALSE),"NO EXISTE") -> VANISH BLANCO | F27: =IFERROR(VLOOKUP(COMPRAS[[#This Row],[CODIGO]],INVENTARIO[],3,FALSE),"NO EXISTE") -> LAVANDERIA | G27: 700 | H27: 12 | I27: =COMPRAS[[#This Row],[COSTO UNITARIO]]*COMPRAS[[#This Row],[CANTIDAD]] -> 8400
A28: A022 | B28: 45945 | C28: =TEXT(COMPRAS[[#This Row],[FECHA]],"[$-es-CL]mmmm") -> octubre | D28: {=YEAR(IF(ISNUMBER(COMPRAS[[#This Row],[FECHA]]),COMPRAS[[#This Row],[FECHA]],FECHA.VALOR(COMPRAS[[#This Row],[FECHA]])))} -> 2025 | E28: =IFERROR(VLOOKUP(COMPRAS[[#This Row],[CODIGO]],INVENTARIO[],2,FALSE),"NO EXISTE") -> VANISH ROSADO | F28: =IFERROR(VLOOKUP(COMPRAS[[#This Row],[CODIGO]],INVENTARIO[],3,FALSE),"NO EXISTE") -> LAVANDERIA | G28: 1110 | H28: 9 | I28: =COMPRAS[[#This Row],[COSTO UNITARIO]]*COMPRAS[[#This Row],[CANTIDAD]] -> 9990
A29: A023 | B29: 45945 | C29: =TEXT(COMPRAS[[#This Row],[FECHA]],"[$-es-CL]mmmm") -> octubre | D29: {=YEAR(IF(ISNUMBER(COMPRAS[[#This Row],[FECHA]]),COMPRAS[[#This Row],[FECHA]],FECHA.VALOR(COMPRAS[[#This Row],[FECHA]])))} -> 2025 | E29: =IFERROR(VLOOKUP(COMPRAS[[#This Row],[CODIGO]],INVENTARIO[],2,FALSE),"NO EXISTE") -> CLORO CONCENTRADO DE 5 LITROS | F29: =IFERROR(VLOOKUP(COMPRAS[[#This Row],[CODIGO]],INVENTARIO[],3,FALSE),"NO EXISTE") -> DESINFECCIÓN | G29: 1000 | H29: 10 | I29: =COMPRAS[[#This Row],[COSTO UNITARIO]]*COMPRAS[[#This Row],[CANTIDAD]] -> 10000
A30: A024 | B30: 45945 | C30: =TEXT(COMPRAS[[#This Row],[FECHA]],"[$-es-CL]mmmm") -> octubre | D30: {=YEAR(IF(ISNUMBER(COMPRAS[[#This Row],[FECHA]]),COMPRAS[[#This Row],[FECHA]],FECHA.VALOR(COMPRAS[[#This Row],[FECHA]])))} -> 2025 | E30: =IFERROR(VLOOKUP(COMPRAS[[#This Row],[CODIGO]],INVENTARIO[],2,FALSE),"NO EXISTE") -> CLORINDA DE 1 LITRO | F30: =IFERROR(VLOOKUP(COMPRAS[[#This Row],[CODIGO]],INVENTARIO[],3,FALSE),"NO EXISTE") -> DESINFECCIÓN | G30: 667 | H30: 12 | I30: =COMPRAS[[#This Row],[COSTO UNITARIO]]*COMPRAS[[#This Row],[CANTIDAD]] -> 8004
A31: A025 | B31: 45945 | C31: =TEXT(COMPRAS[[#This Row],[FECHA]],"[$-es-CL]mmmm") -> octubre | D31: {=YEAR(IF(ISNUMBER(COMPRAS[[#This Row],[FECHA]]),COMPRAS[[#This Row],[FECHA]],FECHA.VALOR(COMPRAS[[#This Row],[FECHA]])))} -> 2025 | E31: =IFERROR(VLOOKUP(COMPRAS[[#This Row],[CODIGO]],INVENTARIO[],2,FALSE),"NO EXISTE") -> CLORO GEL CLOROX | F31: =IFERROR(VLOOKUP(COMPRAS[[#This Row],[CODIGO]],INVENTARIO[],3,FALSE),"NO EXISTE") -> DESINFECCIÓN | G31: 666 | H31: 9 | I31: =COMPRAS[[#This Row],[COSTO UNITARIO]]*COMPRAS[[#This Row],[CANTIDAD]] -> 5994
A32: A026 | B32: 45945 | C32: =TEXT(COMPRAS[[#This Row],[FECHA]],"[$-es-CL]mmmm") -> octubre | D32: {=YEAR(IF(ISNUMBER(COMPRAS[[#This Row],[FECHA]]),COMPRAS[[#This Row],[FECHA]],FECHA.VALOR(COMPRAS[[#This Row],[FECHA]])))} -> 2025 | E32: =IFERROR(VLOOKUP(COMPRAS[[#This Row],[CODIGO]],INVENTARIO[],2,FALSE),"NO EXISTE") -> CLORO IGENIX LIQUIDO | F32: =IFERROR(VLOOKUP(COMPRAS[[#This Row],[CODIGO]],INVENTARIO[],3,FALSE),"NO EXISTE") -> DESINFECCIÓN | G32: 599 | H32: 12 | I32: =COMPRAS[[#This Row],[COSTO UNITARIO]]*COMPRAS[[#This Row],[CANTIDAD]] -> 7188
A33: A027 | B33: 45945 | C33: =TEXT(COMPRAS[[#This Row],[FECHA]],"[$-es-CL]mmmm") -> octubre | D33: {=YEAR(IF(ISNUMBER(COMPRAS[[#This Row],[FECHA]]),COMPRAS[[#This Row],[FECHA]],FECHA.VALOR(COMPRAS[[#This Row],[FECHA]])))} -> 2025 | E33: =IFERROR(VLOOKUP(COMPRAS[[#This Row],[CODIGO]],INVENTARIO[],2,FALSE),"NO EXISTE") -> CLORINDA CLORO GEL | F33: =IFERROR(VLOOKUP(COMPRAS[[#This Row],[CODIGO]],INVENTARIO[],3,FALSE),"NO EXISTE") -> DESINFECCIÓN | G33: 599 | H33: 12 | I33: =COMPRAS[[#This Row],[COSTO UNITARIO]]*COMPRAS[[#This Row],[CANTIDAD]] -> 7188
A34: A028 | B34: 45945 | C34: =TEXT(COMPRAS[[#This Row],[FECHA]],"[$-es-CL]mmmm") -> octubre | D34: {=YEAR(IF(ISNUMBER(COMPRAS[[#This Row],[FECHA]]),COMPRAS[[#This Row],[FECHA]],FECHA.VALOR(COMPRAS[[#This Row],[FECHA]])))} -> 2025 | E34: =IFERROR(VLOOKUP(COMPRAS[[#This Row],[CODIGO]],INVENTARIO[],2,FALSE),"NO EXISTE") -> CLORINDA CLORO GEL EXCEL MORADO | F34: =IFERROR(VLOOKUP(COMPRAS[[#This Row],[CODIGO]],INVENTARIO[],3,FALSE),"NO EXISTE") -> DESINFECCIÓN | G34: 833 | H34: 12 | I34: =COMPRAS[[#This Row],[COSTO UNITARIO]]*COMPRAS[[#This Row],[CANTIDAD]] -> 9996
A35: A029 | B35: 45945 | C35: =TEXT(COMPRAS[[#This Row],[FECHA]],"[$-es-CL]mmmm") -> octubre | D35: {=YEAR(IF(ISNUMBER(COMPRAS[[#This Row],[FECHA]]),COMPRAS[[#This Row],[FECHA]],FECHA.VALOR(COMPRAS[[#This Row],[FECHA]])))} -> 2025 | E35: =IFERROR(VLOOKUP(COMPRAS[[#This Row],[CODIGO]],INVENTARIO[],2,FALSE),"NO EXISTE") -> CLORINDA CLORO GEL EXCEL AMARILLO | F35: =IFERROR(VLOOKUP(COMPRAS[[#This Row],[CODIGO]],INVENTARIO[],3,FALSE),"NO EXISTE") -> DESINFECCIÓN | G35: 1443 | H35: 9 | I35: =COMPRAS[[#This Row],[COSTO UNITARIO]]*COMPRAS[[#This Row],[CANTIDAD]] -> 12987
A36: A030 | B36: 45945 | C36: =TEXT(COMPRAS[[#This Row],[FECHA]],"[$-es-CL]mmmm") -> octubre | D36: {=YEAR(IF(ISNUMBER(COMPRAS[[#This Row],[FECHA]]),COMPRAS[[#This Row],[FECHA]],FECHA.VALOR(COMPRAS[[#This Row],[FECHA]])))} -> 2025 | E36: =IFERROR(VLOOKUP(COMPRAS[[#This Row],[CODIGO]],INVENTARIO[],2,FALSE),"NO EXISTE") -> ANTIGRASA SPUM DE 2 LITROS | F36: =IFERROR(VLOOKUP(COMPRAS[[#This Row],[CODIGO]],INVENTARIO[],3,FALSE),"NO EXISTE") -> COCINA | G36: 698 | H36: 5 | I36: =COMPRAS[[#This Row],[COSTO UNITARIO]]*COMPRAS[[#This Row],[CANTIDAD]] -> 3490
A37: A031 | B37: 45945 | C37: =TEXT(COMPRAS[[#This Row],[FECHA]],"[$-es-CL]mmmm") -> octubre | D37: {=YEAR(IF(ISNUMBER(COMPRAS[[#This Row],[FECHA]]),COMPRAS[[#This Row],[FECHA]],FECHA.VALOR(COMPRAS[[#This Row],[FECHA]])))} -> 2025 | E37: =IFERROR(VLOOKUP(COMPRAS[[#This Row],[CODIGO]],INVENTARIO[],2,FALSE),"NO EXISTE") -> ANTIGRASA SPUM DE 500 ML | F37: =IFERROR(VLOOKUP(COMPRAS[[#This Row],[CODIGO]],INVENTARIO[],3,FALSE),"NO EXISTE") -> COCINA | G37: 700 | H37: 12 | I37: =COMPRAS[[#This Row],[COSTO UNITARIO]]*COMPRAS[[#This Row],[CANTIDAD]] -> 8400
A38: A032 | B38: 45945 | C38: =TEXT(COMPRAS[[#This Row],[FECHA]],"[$-es-CL]mmmm") -> octubre | D38: {=YEAR(IF(ISNUMBER(COMPRAS[[#This Row],[FECHA]]),COMPRAS[[#This Row],[FECHA]],FECHA.VALOR(COMPRAS[[#This Row],[FECHA]])))} -> 2025 | E38: =IFERROR(VLOOKUP(COMPRAS[[#This Row],[CODIGO]],INVENTARIO[],2,FALSE),"NO EXISTE") -> SACASARRO SPUM DE 2 LITROS | F38: =IFERROR(VLOOKUP(COMPRAS[[#This Row],[CODIGO]],INVENTARIO[],3,FALSE),"NO EXISTE") -> COCINA | G38: 1790 | H38: 6 | I38: =COMPRAS[[#This Row],[COSTO UNITARIO]]*COMPRAS[[#This Row],[CANTIDAD]] -> 10740
... A44: A038 | B44: 45945 | C44: =TEXT(COMPRAS[[#This Row],[FECHA]],"[$-es-CL]mmmm") -> octubre | D44: {=YEAR(IF(ISNUMBER(COMPRAS[[#This Row],[FECHA]]),COMPRAS[[#This Row],[FECHA]],FECHA.VALOR(COMPRAS[[#This Row],[FECHA]])))} -> 2025 | E44: =IFERROR(VLOOKUP(COMPRAS[[#This Row],[CODIGO]],INVENTARIO[],2,FALSE),"NO EXISTE") -> CIF | F44: =IFERROR(VLOOKUP(COMPRAS[[#This Row],[CODIGO]],INVENTARIO[],3,FALSE),"NO EXISTE") -> COCINA | G44: 990 | H44: 12 | I44: =COMPRAS[[#This Row],[COSTO UNITARIO]]*COMPRAS[[#This Row],[CANTIDAD]] -> 11880
A45: A039 | B45: 45945 | C45: =TEXT(COMPRAS[[#This Row],[FECHA]],"[$-es-CL]mmmm") -> octubre | D45: {=YEAR(IF(ISNUMBER(COMPRAS[[#This Row],[FECHA]]),COMPRAS[[#This Row],[FECHA]],FECHA.VALOR(COMPRAS[[#This Row],[FECHA]])))} -> 2025 | E45: =IFERROR(VLOOKUP(COMPRAS[[#This Row],[CODIGO]],INVENTARIO[],2,FALSE),"NO EXISTE") -> LUSTRA MUEBLES | F45: =IFERROR(VLOOKUP(COMPRAS[[#This Row],[CODIGO]],INVENTARIO[],3,FALSE),"NO EXISTE") -> COCINA | H45: 50 | I45: =COMPRAS[[#This Row],[COSTO UNITARIO]]*COMPRAS[[#This Row],[CANTIDAD]] -> 0
A46: A040 | B46: 45945 | C46: =TEXT(COMPRAS[[#This Row],[FECHA]],"[$-es-CL]mmmm") -> octubre | D46: {=YEAR(IF(ISNUMBER(COMPRAS[[#This Row],[FECHA]]),COMPRAS[[#This Row],[FECHA]],FECHA.VALOR(COMPRAS[[#This Row],[FECHA]])))} -> 2025 | E46: =IFERROR(VLOOKUP(COMPRAS[[#This Row],[CODIGO]],INVENTARIO[],2,FALSE),"NO EXISTE") -> LIMPIA VIDRIOS DE 500CC | F46: =IFERROR(VLOOKUP(COMPRAS[[#This Row],[CODIGO]],INVENTARIO[],3,FALSE),"NO EXISTE") -> COCINA | G46: 500 | H46: 50 | I46: =COMPRAS[[#This Row],[COSTO UNITARIO]]*COMPRAS[[#This Row],[CANTIDAD]] -> 25000
A47: A041 | B47: 45945 | C47: =TEXT(COMPRAS[[#This Row],[FECHA]],"[$-es-CL]mmmm") -> octubre | D47: {=YEAR(IF(ISNUMBER(COMPRAS[[#This Row],[FECHA]]),COMPRAS[[#This Row],[FECHA]],FECHA.VALOR(COMPRAS[[#This Row],[FECHA]])))} -> 2025 | E47: =IFERROR(VLOOKUP(COMPRAS[[#This Row],[CODIGO]],INVENTARIO[],2,FALSE),"NO EXISTE") -> LIMPIA PISOS FLOTANTE | F47: =IFERROR(VLOOKUP(COMPRAS[[#This Row],[CODIGO]],INVENTARIO[],3,FALSE),"NO EXISTE") -> COCINA | G47: 85 | H47: 400 | I47: =COMPRAS[[#This Row],[COSTO UNITARIO]]*COMPRAS[[#This Row],[CANTIDAD]] -> 34000
...

Sheet VENTAS
A1: VENTAS
J4: TOTAL VENTA | K4: TOTAL UTILIDAD
J5: =SUBTOTAL(9,J6:J212) -> 0 | K5: =SUBTOTAL(9,K6:K212) -> 0
A6: CODIGO | B6: FECHA | C6: MES | D6: AÑO | E6: NOMBRE DEL PRODUCTO | F6: CATEGORIA | G6: PRECIO DE VENTA | H6: COSTO UNITARIO | I6: CANTIDAD | J6: TOTAL DE LA VENTA | K6: UTILIDAD
A7: A001 | B7: 45047 | C7: =TEXT(VENTAS[[#This Row],[FECHA]],"[$-es-CL]mmmm") -> mayo | D7: {=YEAR(IF(ISNUMBER(VENTAS[[#This Row],[FECHA]]),VENTAS[[#This Row],[FECHA]],FECHA.VALOR(VENTAS[[#This Row],[FECHA]])))} -> 2023 | E7: =IFERROR(VLOOKUP(VENTAS[[#This Row],[CODIGO]],INVENTARIO[],2,FALSE),"NO EXISTE") -> DETERGENTE BIO AZUL DE 5 LITROS | F7: =IFERROR(VLOOKUP(VENTAS[[#This Row],[CODIGO]],INVENTARIO[],3,FALSE),"NO EXISTE") -> LAVANDERIA | G7: =IFERROR(VLOOKUP(VENTAS[[#This Row],[CODIGO]],INVENTARIO[],8,FALSE),"NO EXISTE") -> 1800 | H7: =IFERROR(VLOOKUP(VENTAS[[#This Row],[CODIGO]],INVENTARIO[],7,FALSE),"NO EXISTE") -> 920 | I7: 0 | J7: =VENTAS[[#This Row],[PRECIO DE VENTA]]*VENTAS[[#This Row],[CANTIDAD]] -> 0 | K7: =VENTAS[[#This Row],[TOTAL DE LA VENTA]]-VENTAS[[#This Row],[COSTO UNITARIO]]*VENTAS[[#This Row],[CANTIDAD]] -> 0
A8: A002 | C8: =TEXT(VENTAS[[#This Row],[FECHA]],"[$-es-CL]mmmm") -> enero | D8: {=YEAR(IF(ISNUMBER(VENTAS[[#This Row],[FECHA]]),VENTAS[[#This Row],[FECHA]],FECHA.VALOR(VENTAS[[#This Row],[FECHA]])))} -> #NAME? | E8: =IFERROR(VLOOKUP(VENTAS[[#This Row],[CODIGO]],INVENTARIO[],2,FALSE),"NO EXISTE") -> DETERGENTE BIO VERDE DE 5 LITROS | F8: =IFERROR(VLOOKUP(VENTAS[[#This Row],[CODIGO]],INVENTARIO[],3,FALSE),"NO EXISTE") -> LAVANDERIA | G8: =IFERROR(VLOOKUP(VENTAS[[#This Row],[CODIGO]],INVENTARIO[],8,FALSE),"NO EXISTE") -> 1800 | H8: =IFERROR(VLOOKUP(VENTAS[[#This Row],[CODIGO]],INVENTARIO[],7,FALSE),"NO EXISTE") -> 920 | I8: 0 | J8: =VENTAS[[#This Row],[PRECIO DE VENTA]]*VENTAS[[#This Row],[CANTIDAD]] -> 0 | K8: =VENTAS[[#This Row],[TOTAL DE LA VENTA]]-VENTAS[[#This Row],[COSTO UNITARIO]]*VENTAS[[#This Row],[CANTIDAD]] -> 0
A9: A003 | C9: =TEXT(VENTAS[[#This Row],[FECHA]],"[$-es-CL]mmmm") -> enero | D9: {=YEAR(IF(ISNUMBER(VENTAS[[#This Row],[FECHA]]),VENTAS[[#This Row],[FECHA]],FECHA.VALOR(VENTAS[[#This Row],[FECHA]])))} -> #NAME? | E9: =IFERROR(VLOOKUP(VENTAS[[#This Row],[CODIGO]],INVENTARIO[],2,FALSE),"NO EXISTE") -> DETERGENTE MORADO CON SUAVIZANTE DE 5 LITROS | F9: =IFERROR(VLOOKUP(VENTAS[[#This Row],[CODIGO]],INVENTARIO[],3,FALSE),"NO EXISTE") -> LAVANDERIA | G9: =IFERROR(VLOOKUP(VENTAS[[#This Row],[CODIGO]],INVENTARIO[],8,FALSE),"NO EXISTE") -> 2500 | H9: =IFERROR(VLOOKUP(VENTAS[[#This Row],[CODIGO]],INVENTARIO[],7,FALSE),"NO EXISTE") -> 1490 | I9: 0 | J9: =VENTAS[[#This Row],[PRECIO DE VENTA]]*VENTAS[[#This Row],[CANTIDAD]] -> 0 | K9: =VENTAS[[#This Row],[TOTAL DE LA VENTA]]-VENTAS[[#This Row],[COSTO UNITARIO]]*VENTAS[[#This Row],[CANTIDAD]] -> 0
A10: A004 | C10: =TEXT(VENTAS[[#This Row],[FECHA]],"[$-es-CL]mmmm") -> enero | D10: {=YEAR(IF(ISNUMBER(VENTAS[[#This Row],[FECHA]]),VENTAS[[#This Row],[FECHA]],FECHA.VALOR(VENTAS[[#This Row],[FECHA]])))} -> #NAME? | E10: =IFERROR(VLOOKUP(VENTAS[[#This Row],[CODIGO]],INVENTARIO[],2,FALSE),"NO EXISTE") -> DETERGENTE BLANCO CON SUAVIZANTE DE 5 LITROS | F10: =IFERROR(VLOOKUP(VENTAS[[#This Row],[CODIGO]],INVENTARIO[],3,FALSE),"NO EXISTE") -> LAVANDERIA | G10: =IFERROR(VLOOKUP(VENTAS[[#This Row],[CODIGO]],INVENTARIO[],8,FALSE),"NO EXISTE") -> 2500 | H10: =IFERROR(VLOOKUP(VENTAS[[#This Row],[CODIGO]],INVENTARIO[],7,FALSE),"NO EXISTE") -> 1490 | I10: 0 | J10: =VENTAS[[#This Row],[PRECIO DE VENTA]]*VENTAS[[#This Row],[CANTIDAD]] -> 0 | K10: =VENTAS[[#This Row],[TOTAL DE LA VENTA]]-VENTAS[[#This Row],[COSTO UNITARIO]]*VENTAS[[#This Row],[CANTIDAD]] -> 0
A11: A005 | C11: =TEXT(VENTAS[[#This Row],[FECHA]],"[$-es-CL]mmmm") -> enero | D11: {=YEAR(IF(ISNUMBER(VENTAS[[#This Row],[FECHA]]),VENTAS[[#This Row],[FECHA]],FECHA.VALOR(VENTAS[[#This Row],[FECHA]])))} -> #NAME? | E11: =IFERROR(VLOOKUP(VENTAS[[#This Row],[CODIGO]],INVENTARIO[],2,FALSE),"NO EXISTE") -> DETERGENTE CELESTE CON SUAVIZANTE DE 5 LITROS | F11: =IFERROR(VLOOKUP(VENTAS[[#This Row],[CODIGO]],INVENTARIO[],3,FALSE),"NO EXISTE") -> LAVANDERIA | G11: =IFERROR(VLOOKUP(VENTAS[[#This Row],[CODIGO]],INVENTARIO[],8,FALSE),"NO EXISTE") -> 2500 | H11: =IFERROR(VLOOKUP(VENTAS[[#This Row],[CODIGO]],INVENTARIO[],7,FALSE),"NO EXISTE") -> 1490 | J11: =VENTAS[[#This Row],[PRECIO DE VENTA]]*VENTAS[[#This Row],[CANTIDAD]] -> 0 | K11: =VENTAS[[#This Row],[TOTAL DE LA VENTA]]-VENTAS[[#This Row],[COSTO UNITARIO]]*VENTAS[[#This Row],[CANTIDAD]] -> 0
A12: A006 | C12: =TEXT(VENTAS[[#This Row],[FECHA]],"[$-es-CL]mmmm") -> enero | D12: {=YEAR(IF(ISNUMBER(VENTAS[[#This Row],[FECHA]]),VENTAS[[#This Row],[FECHA]],FECHA.VALOR(VENTAS[[#This Row],[FECHA]])))} -> #NAME? | E12: =IFERROR(VLOOKUP(VENTAS[[#This Row],[CODIGO]],INVENTARIO[],2,FALSE),"NO EXISTE") -> DETERGENTE NARANJO CON SUAVIZANTE DE 5 LITROS | F12: =IFERROR(VLOOKUP(VENTAS[[#This Row],[CODIGO]],INVENTARIO[],3,FALSE),"NO EXISTE") -> LAVANDERIA | G12: =IFERROR(VLOOKUP(VENTAS[[#This Row],[CODIGO]],INVENTARIO[],8,FALSE),"NO EXISTE") -> 2500 | H12: =IFERROR(VLOOKUP(VENTAS[[#This Row],[CODIGO]],INVENTARIO[],7,FALSE),"NO EXISTE") -> 1490 | J12: =VENTAS[[#This Row],[PRECIO DE VENTA]]*VENTAS[[#This Row],[CANTIDAD]] -> 0 | K12: =VENTAS[[#This Row],[TOTAL DE LA VENTA]]-VENTAS[[#This Row],[COSTO UNITARIO]]*VENTAS[[#This Row],[CANTIDAD]] -> 0
A13: A007 | C13: =TEXT(VENTAS[[#This Row],[FECHA]],"[$-es-CL]mmmm") -> enero | D13: {=YEAR(IF(ISNUMBER(VENTAS[[#This Row],[FECHA]]),VENTAS[[#This Row],[FECHA]],FECHA.VALOR(VENTAS[[#This Row],[FECHA]])))} -> #NAME? | E13: =IFERROR(VLOOKUP(VENTAS[[#This Row],[CODIGO]],INVENTARIO[],2,FALSE),"NO EXISTE") -> DETERGENTE ROSADO CON SUAVIZANTE DE 5 LITROS | F13: =IFERROR(VLOOKUP(VENTAS[[#This Row],[CODIGO]],INVENTARIO[],3,FALSE),"NO EXISTE") -> LAVANDERIA | G13: =IFERROR(VLOOKUP(VENTAS[[#This Row],[CODIGO]],INVENTARIO[],8,FALSE),"NO EXISTE") -> 2500 | H13: =IFERROR(VLOOKUP(VENTAS[[#This Row],[CODIGO]],INVENTARIO[],7,FALSE),"NO EXISTE") -> 1490 | J13: =VENTAS[[#This Row],[PRECIO DE VENTA]]*VENTAS[[#This Row],[CANTIDAD]] -> 0 | K13: =VENTAS[[#This Row],[TOTAL DE LA VENTA]]-VENTAS[[#This Row],[COSTO UNITARIO]]*VENTAS[[#This Row],[CANTIDAD]] -> 0
A14: A008 | C14: =TEXT(VENTAS[[#This Row],[FECHA]],"[$-es-CL]mmmm") -> enero | D14: {=YEAR(IF(ISNUMBER(VENTAS[[#This Row],[FECHA]]),VENTAS[[#This Row],[FECHA]],FECHA.VALOR(VENTAS[[#This Row],[FECHA]])))} -> #NAME? | E14: =IFERROR(VLOOKUP(VENTAS[[#This Row],[CODIGO]],INVENTARIO[],2,FALSE),"NO EXISTE") -> DETERGENTE PREMIUM AROMA OMO DE 3 LITROS (PACK DE 4 UNID) | F14: =IFERROR(VLOOKUP(VENTAS[[#This Row],[CODIGO]],INVENTARIO[],3,FALSE),"NO EXISTE") -> LAVANDERIA | G14: =IFERROR(VLOOKUP(VENTAS[[#This Row],[CODIGO]],INVENTARIO[],8,FALSE),"NO EXISTE") -> 3000 | H14: =IFERROR(VLOOKUP(VENTAS[[#This Row],[CODIGO]],INVENTARIO[],7,FALSE),"NO EXISTE") -> 1350 | J14: =VENTAS[[#This Row],[PRECIO DE VENTA]]*VENTAS[[#This Row],[CANTIDAD]] -> 0 | K14: =VENTAS[[#This Row],[TOTAL DE LA VENTA]]-VENTAS[[#This Row],[COSTO UNITARIO]]*VENTAS[[#This Row],[CANTIDAD]] -> 0
A15: A009 | C15: =TEXT(VENTAS[[#This Row],[FECHA]],"[$-es-CL]mmmm") -> enero | D15: {=YEAR(IF(ISNUMBER(VENTAS[[#This Row],[FECHA]]),VENTAS[[#This Row],[FECHA]],FECHA.VALOR(VENTAS[[#This Row],[FECHA]])))} -> #NAME? | E15: =IFERROR(VLOOKUP(VENTAS[[#This Row],[CODIGO]],INVENTARIO[],2,FALSE),"NO EXISTE") -> DETERGENTE DE BEBÉ 3 LITROS | F15: =IFERROR(VLOOKUP(VENTAS[[#This Row],[CODIGO]],INVENTARIO[],3,FALSE),"NO EXISTE") -> LAVANDERIA | G15: =IFERROR(VLOOKUP(VENTAS[[#This Row],[CODIGO]],INVENTARIO[],8,FALSE),"NO EXISTE") -> 4000 | H15: =IFERROR(VLOOKUP(VENTAS[[#This Row],[CODIGO]],INVENTARIO[],7,FALSE),"NO EXISTE") -> 2450 | J15: =VENTAS[[#This Row],[PRECIO DE VENTA]]*VENTAS[[#This Row],[CANTIDAD]] -> 0 | K15: =VENTAS[[#This Row],[TOTAL DE LA VENTA]]-VENTAS[[#This Row],[COSTO UNITARIO]]*VENTAS[[#This Row],[CANTIDAD]] -> 0
A16: A010 | C16: =TEXT(VENTAS[[#This Row],[FECHA]],"[$-es-CL]mmmm") -> enero | D16: {=YEAR(IF(ISNUMBER(VENTAS[[#This Row],[FECHA]]),VENTAS[[#This Row],[FECHA]],FECHA.VALOR(VENTAS[[#This Row],[FECHA]])))} -> #NAME? | E16: =IFERROR(VLOOKUP(VENTAS[[#This Row],[CODIGO]],INVENTARIO[],2,FALSE),"NO EXISTE") -> DETERGENTE OMO PARA DILUIR 3 LITROS | F16: =IFERROR(VLOOKUP(VENTAS[[#This Row],[CODIGO]],INVENTARIO[],3,FALSE),"NO EXISTE") -> LAVANDERIA | G16: =IFERROR(VLOOKUP(VENTAS[[#This Row],[CODIGO]],INVENTARIO[],8,FALSE),"NO EXISTE") -> 4500 | H16: =IFERROR(VLOOKUP(VENTAS[[#This Row],[CODIGO]],INVENTARIO[],7,FALSE),"NO EXISTE") -> 3490 | J16: =VENTAS[[#This Row],[PRECIO DE VENTA]]*VENTAS[[#This Row],[CANTIDAD]] -> 0 | K16: =VENTAS[[#This Row],[TOTAL DE LA VENTA]]-VENTAS[[#This Row],[COSTO UNITARIO]]*VENTAS[[#This Row],[CANTIDAD]] -> 0
A17: A011 | C17: =TEXT(VENTAS[[#This Row],[FECHA]],"[$-es-CL]mmmm") -> enero | D17: {=YEAR(IF(ISNUMBER(VENTAS[[#This Row],[FECHA]]),VENTAS[[#This Row],[FECHA]],FECHA.VALOR(VENTAS[[#This Row],[FECHA]])))} -> #NAME? | E17: =IFERROR(VLOOKUP(VENTAS[[#This Row],[CODIGO]],INVENTARIO[],2,FALSE),"NO EXISTE") -> DETERGENTE OMO DE 400 ML | F17: =IFERROR(VLOOKUP(VENTAS[[#This Row],[CODIGO]],INVENTARIO[],3,FALSE),"NO EXISTE") -> LAVANDERIA | G17: =IFERROR(VLOOKUP(VENTAS[[#This Row],[CODIGO]],INVENTARIO[],8,FALSE),"NO EXISTE") -> 1000 | H17: =IFERROR(VLOOKUP(VENTAS[[#This Row],[CODIGO]],INVENTARIO[],7,FALSE),"NO EXISTE") -> 690 | J17: =VENTAS[[#This Row],[PRECIO DE VENTA]]*VENTAS[[#This Row],[CANTIDAD]] -> 0 | K17: =VENTAS[[#This Row],[TOTAL DE LA VENTA]]-VENTAS[[#This Row],[COSTO UNITARIO]]*VENTAS[[#This Row],[CANTIDAD]] -> 0
A18: A012 | C18: =TEXT(VENTAS[[#This Row],[FECHA]],"[$-es-CL]mmmm") -> enero | D18: {=YEAR(IF(ISNUMBER(VENTAS[[#This Row],[FECHA]]),VENTAS[[#This Row],[FECHA]],FECHA.VALOR(VENTAS[[#This Row],[FECHA]])))} -> #NAME? | E18: =IFERROR(VLOOKUP(VENTAS[[#This Row],[CODIGO]],INVENTARIO[],2,FALSE),"NO EXISTE") -> DETERGENTE OMO LIQUIDO BIDÓN 3 LITROS | F18: =IFERROR(VLOOKUP(VENTAS[[#This Row],[CODIGO]],INVENTARIO[],3,FALSE),"NO EXISTE") -> LAVANDERIA | G18: =IFERROR(VLOOKUP(VENTAS[[#This Row],[CODIGO]],INVENTARIO[],8,FALSE),"NO EXISTE") -> 0 | H18: =IFERROR(VLOOKUP(VENTAS[[#This Row],[CODIGO]],INVENTARIO[],7,FALSE),"NO EXISTE") -> 0 | J18: =VENTAS[[#This Row],[PRECIO DE VENTA]]*VENTAS[[#This Row],[CANTIDAD]] -> 0 | K18: =VENTAS[[#This Row],[TOTAL DE LA VENTA]]-VENTAS[[#This Row],[COSTO UNITARIO]]*VENTAS[[#This Row],[CANTIDAD]] -> 0
A19: A013 | C19: =TEXT(VENTAS[[#This Row],[FECHA]],"[$-es-CL]mmmm") -> enero | D19: {=YEAR(IF(ISNUMBER(VENTAS[[#This Row],[FECHA]]),VENTAS[[#This Row],[FECHA]],FECHA.VALOR(VENTAS[[#This Row],[FECHA]])))} -> #NAME? | E19: =IFERROR(VLOOKUP(VENTAS[[#This Row],[CODIGO]],INVENTARIO[],2,FALSE),"NO EXISTE") -> DETERGENTE BIO KLINNING AZUL | F19: =IFERROR(VLOOKUP(VENTAS[[#This Row],[CODIGO]],INVENTARIO[],3,FALSE),"NO EXISTE") -> LAVANDERIA | G19: =IFERROR(VLOOKUP(VENTAS[[#This Row],[CODIGO]],INVENTARIO[],8,FALSE),"NO EXISTE") -> 0 | H19: =IFERROR(VLOOKUP(VENTAS[[#This Row],[CODIGO]],INVENTARIO[],7,FALSE),"NO EXISTE") -> 950 | J19: =VENTAS[[#This Row],[PRECIO DE VENTA]]*VENTAS[[#This Row],[CANTIDAD]] -> 0 | K19: =VENTAS[[#This Row],[TOTAL DE LA VENTA]]-VENTAS[[#This Row],[COSTO UNITARIO]]*VENTAS[[#This Row],[CANTIDAD]] -> 0
